Workbook

Sheet Securities
A1: TIPS-Treasury Arbitrage - Case Study (trade date 5 October 2006)
A3: The two securities
B4: TIPS | C4: Treasury note
A5: CUSIP | B5: 912828EA | C5: 912828EE
A6: Maturity | B6: 7/15/2015 | C6: 8/15/2015
A7: Issue date | B7: 7/15/2005 | C7: 8/15/2005
A8: Coupon | B8: 1.875% | C8: 4.250%
A9: First coupon date | B9: 1/15/2006 | C9: 2/15/2006
A10: Second coupon date | B10: 7/15/2006 | C10: 8/15/2006
A11: Reference CPI on issue date | B11: 194.50968 | C11: -
A12: Price quote | B12: 96-20 | C12: 97-15+
A14: Bloomberg screenshots below are taken on the trade date. The pricing math is on the Step1_Prices / Step2_CashFlows / Result tabs.
A16: TIPS 912828EA - Description (Bloomberg DES)
A41: TIPS 912828EA - Price quotes (Bloomberg)
A61: TIPS 912828EA - Price history (Bloomberg GP)
A78: Treasury note 912828EE - Description (Bloomberg DES)
A103: Treasury note 912828EE - Price quotes (Bloomberg)
A115: Treasury note 912828EE - Price history (Bloomberg GP)

Sheet MarketData
A1: Market data on the trade date (5 October 2006)
A3: (a) Bloomberg inflation-swap curve - reference
A4: Tenor (yrs) | B4: Swap rate
A5: 1 | B5: 0.0185
A6: 2 | B6: 0.02133
A7: 3 | B7: 0.02313
A8: 4 | B8: 0.02425
A9: 5 | B9: 0.02503
A10: 6 | B10: 0.02543
A11: 7 | B11: 0.0258
A12: 8 | B12: 0.02623
A13: 9 | B13: 0.02648
A14: 10 | B14: 0.02683
A15: 12 | B15: 0.02733
A16: 15 | B16: 0.02798
... A19: 30 | B19: 0.0317
A20: (b) Inputs at the 18 TIPS coupon dates - used by Step2
A21: Date | B21: Inflation swap rate | C21: Swap tenor (yrs) | D21: STRIPS price
A22: 39097 | B22: 0.014123 | C22: 0.2795 | D22: 98.665
A23: 39278 | B23: 0.017091 | C23: 0.7753 | D23: 96.304
A24: 39462 | B24: 0.019628 | C24: 1.2795 | D24: 94.134
A25: 39644 | B25: 0.020925 | C25: 1.7781 | D25: 92.089
A26: 39828 | B26: 0.02196 | C26: 2.2822 | D26: 90.102
A27: 40009 | B27: 0.022847 | C27: 2.7781 | D27: 88.137
A28: 40193 | B28: 0.023544 | C28: 3.2822 | D28: 86.247
A29: 40374 | B29: 0.024078 | C29: 3.7781 | D29: 84.43
A30: 40558 | B30: 0.024534 | C30: 4.2822 | D30: 82.618
A31: 40739 | B31: 0.024914 | C31: 4.7781 | D31: 80.95
A32: 40923 | B32: 0.02518 | C32: 5.2822 | D32: 78.678
A33: 41105 | B33: 0.025364 | C33: 5.7808 | D33: 76.863
... A39: 42200 | B39: 0.026458 | C39: 8.7808 | D39: 66.51
A41: Swap rates/tenors and STRIPS prices are interpolated to the TIPS coupon dates and seasonally adjusted; see Fleckenstein, Longstaff & Lustig (2014). Yellow = input.
A43: Swap tenor day-count example (first row, 0.2795 yr): (31-5) days in Oct + 30 Nov + 31 Dec + 15 Jan = 102 days, and 102 / 365 = 0.2795. The other tenors are computed the same way.

Sheet Step1_Prices
A1: Step 1 - Full (dirty) prices = quoted price + accrued interest
A3: Step 1.1 - Treasury note 912828EE
A4: Quoted price 97-15+ ( = 97 + 15/32 + 1/64 ) | B4: =97+15/32+1/64 -> 0
A5: Treasury prices are quoted in 32nds of a point; the trailing '+' adds half a 32nd, i.e. 1/64.
A6: Coupon rate (annual) | B6: 0.0425
A7: Settlement (current) date | B7: 38995
A8: Last coupon date | B8: 38944
A9: Next coupon date | B9: 39128
A10: Day-count convention | B10: Actual / Actual
A11: Days since last coupon (accrued-interest period):
A12: August 2006 - incl. last coupon date (16+1) | B12: 17
A13: September 2006 | B13: 30
A14: October 2006 - excl. settlement date | B14: 4
A15: = Days since last coupon | B15: =SUM(B12:B14) -> 0
A16: Days in coupon period:
A17: August 2006 (31-15) | B17: 16
A18: September 2006 | B18: 30
A19: October 2006 | B19: 31
A20: November 2006 | B20: 30
A21: December 2006 | B21: 31
A22: January 2007 | B22: 31
A23: February 2007 (to the 15th) | B23: 15
A24: = Days in coupon period | B24: =SUM(B17:B23) -> 0
A25: Accrued interest = coupon/2 x 100 x days_since / days_period | B25: =B6/2*100*B15/B24 -> 0
A26: Full (dirty) price = quoted price + accrued interest | B26: =B4+B25 -> 0
A29: Step 1.2 - TIPS 912828EA
A30: Quoted price 96-20 ( = 96 + 20/32 ) | B30: =96+20/32 -> 0
A31: Quoted in 32nds (no '+' tick here). This is the real quoted price; the inflation adjustment is handled separately through the inflation swaps in Step 2.
A32: Coupon rate (annual) | B32: 0.01875
A33: Settlement (current) date | B33: 38995
A34: Last coupon date | B34: 38913
A35: Next coupon date | B35: 39097
A36: Day-count convention | B36: Actual / Actual
A37: Days since last coupon (accrued-interest period):
A38: July 2006 - incl. last coupon date (16+1) | B38: 17
A39: August 2006 | B39: 31
A40: September 2006 | B40: 30
A41: October 2006 - excl. settlement date | B41: 4
A42: = Days since last coupon | B42: =SUM(B38:B41) -> 0
A43: Days in coupon period:
...

Sheet Step2_CashFlows
A1: Step 2 - Replicating cash flows: TIPS + inflation swaps + STRIPS
A3: Parameters and derivation (notebook tables 2.1-2.3)
A4: TIPS real semi-annual coupon c_TIPS = 1.875%/2 x 100 | B4: =0.01875/2*100 -> 0 | D4: Per coupon date t: TIPS + swap = c_TIPS x (1 + P_swap(t)), with P_swap(t) = (1+f_t)^t - 1. The floating I_t/I_0 legs of TIPS and swap cancel, so the net is known today. Maturity adds Face to both the (TIPS+swap) and the T-note legs.
A5: T-note semi-annual coupon c_Tnote = 4.250%/2 x 100 | B5: =0.0425/2*100 -> 0
A6: Face value | B6: 100
A8: Initial cash flows on the trade date (5 Oct 2006)
A9: Long TIPS | B9: =-'Step1_Prices'!B53 -> 0 | C9: (= -TIPS full price)
A10: Short T-note | B10: ='Step1_Prices'!B26 -> 0 | C10: (= +T-note full price, received on the short)
A13: Date | B13: Swap rate f | C13: Tenor T (yrs) | D13: Swap fixed leg (1+f)^T-1 | E13: TIPS + swap | F13: T-note | G13: STRIPS cash flow (=T-note-(TIPS+swap)) | H13: STRIPS price | I13: STRIPS cost (=cf x price/100)
A14: ='MarketData'!A22 -> 0 | B14: ='MarketData'!B22 -> 0 | C14: ='MarketData'!C22 -> 0 | D14: =(1+B14)^C14-1 -> 0 | E14: =$B$4*(1+D14) -> 0 | F14: =$B$5 -> 0 | G14: =F14-E14 -> 0 | H14: ='MarketData'!D22 -> 0 | I14: =G14*H14/100 -> 0
A15: ='MarketData'!A23 -> 0 | B15: ='MarketData'!B23 -> 0 | C15: ='MarketData'!C23 -> 0 | D15: =(1+B15)^C15-1 -> 0 | E15: =$B$4*(1+D15) -> 0 | F15: =$B$5 -> 0 | G15: =F15-E15 -> 0 | H15: ='MarketData'!D23 -> 0 | I15: =G15*H15/100 -> 0
A16: ='MarketData'!A24 -> 0 | B16: ='MarketData'!B24 -> 0 | C16: ='MarketData'!C24 -> 0 | D16: =(1+B16)^C16-1 -> 0 | E16: =$B$4*(1+D16) -> 0 | F16: =$B$5 -> 0 | G16: =F16-E16 -> 0 | H16: ='MarketData'!D24 -> 0 | I16: =G16*H16/100 -> 0
A17: ='MarketData'!A25 -> 0 | B17: ='MarketData'!B25 -> 0 | C17: ='MarketData'!C25 -> 0 | D17: =(1+B17)^C17-1 -> 0 | E17: =$B$4*(1+D17) -> 0 | F17: =$B$5 -> 0 | G17: =F17-E17 -> 0 | H17: ='MarketData'!D25 -> 0 | I17: =G17*H17/100 -> 0
A18: ='MarketData'!A26 -> 0 | B18: ='MarketData'!B26 -> 0 | C18: ='MarketData'!C26 -> 0 | D18: =(1+B18)^C18-1 -> 0 | E18: =$B$4*(1+D18) -> 0 | F18: =$B$5 -> 0 | G18: =F18-E18 -> 0 | H18: ='MarketData'!D26 -> 0 | I18: =G18*H18/100 -> 0
A19: ='MarketData'!A27 -> 0 | B19: ='MarketData'!B27 -> 0 | C19: ='MarketData'!C27 -> 0 | D19: =(1+B19)^C19-1 -> 0 | E19: =$B$4*(1+D19) -> 0 | F19: =$B$5 -> 0 | G19: =F19-E19 -> 0 | H19: ='MarketData'!D27 -> 0 | I19: =G19*H19/100 -> 0
A20: ='MarketData'!A28 -> 0 | B20: ='MarketData'!B28 -> 0 | C20: ='MarketData'!C28 -> 0 | D20: =(1+B20)^C20-1 -> 0 | E20: =$B$4*(1+D20) -> 0 | F20: =$B$5 -> 0 | G20: =F20-E20 -> 0 | H20: ='MarketData'!D28 -> 0 | I20: =G20*H20/100 -> 0
A21: ='MarketData'!A29 -> 0 | B21: ='MarketData'!B29 -> 0 | C21: ='MarketData'!C29 -> 0 | D21: =(1+B21)^C21-1 -> 0 | E21: =$B$4*(1+D21) -> 0 | F21: =$B$5 -> 0 | G21: =F21-E21 -> 0 | H21: ='MarketData'!D29 -> 0 | I21: =G21*H21/100 -> 0
A22: ='MarketData'!A30 -> 0 | B22: ='MarketData'!B30 -> 0 | C22: ='MarketData'!C30 -> 0 | D22: =(1+B22)^C22-1 -> 0 | E22: =$B$4*(1+D22) -> 0 | F22: =$B$5 -> 0 | G22: =F22-E22 -> 0 | H22: ='MarketData'!D30 -> 0 | I22: =G22*H22/100 -> 0
A23: ='MarketData'!A31 -> 0 | B23: ='MarketData'!B31 -> 0 | C23: ='MarketData'!C31 -> 0 | D23: =(1+B23)^C23-1 -> 0 | E23: =$B$4*(1+D23) -> 0 | F23: =$B$5 -> 0 | G23: =F23-E23 -> 0 | H23: ='MarketData'!D31 -> 0 | I23: =G23*H23/100 -> 0
A24: ='MarketData'!A32 -> 0 | B24: ='MarketData'!B32 -> 0 | C24: ='MarketData'!C32 -> 0 | D24: =(1+B24)^C24-1 -> 0 | E24: =$B$4*(1+D24) -> 0 | F24: =$B$5 -> 0 | G24: =F24-E24 -> 0 | H24: ='MarketData'!D32 -> 0 | I24: =G24*H24/100 -> 0
A25: ='MarketData'!A33 -> 0 | B25: ='MarketData'!B33 -> 0 | C25: ='MarketData'!C33 -> 0 | D25: =(1+B25)^C25-1 -> 0 | E25: =$B$4*(1+D25) -> 0 | F25: =$B$5 -> 0 | G25: =F25-E25 -> 0 | H25: ='MarketData'!D33 -> 0 | I25: =G25*H25/100 -> 0
... A30: ='MarketData'!A38 -> 0 | B30: ='MarketData'!B38 -> 0 | C30: ='MarketData'!C38 -> 0 | D30: =(1+B30)^C30-1 -> 0 | E30: =$B$4*(1+D30) -> 0 | F30: =$B$5 -> 0 | G30: =F30-E30 -> 0 | H30: ='MarketData'!D38 -> 0 | I30: =G30*H30/100 -> 0
A31: ='MarketData'!A39 -> 0 | B31: ='MarketData'!B39 -> 0 | C31: ='MarketData'!C39 -> 0 | D31: =(1+B31)^C31-1 -> 0 | E31: =($B$6+$B$4)*(1+D31) -> 0 | F31: =$B$6+$B$5 -> 0 | G31: =F31-E31 -> 0 | H31: ='MarketData'!D39 -> 0 | I31: =G31*H31/100 -> 0
H32: PxSTRIPS = | I32: =SUM(I14:I31) -> 0
A34: PxSTRIPS is the net cost today of the STRIPS leg (long at coupon dates, short at maturity). Carried into the Result tab.

Sheet Result
A1: Result - Is there an arbitrage?
A3: Matched-maturity comparison
A4: TIPS market (full) price | B4: ='Step1_Prices'!B53 -> 0
A5: plus net cost of STRIPS positions (PxSTRIPS; < 0 = proceeds) | B5: ='Step2_CashFlows'!I32 -> 0
A6: Replicating portfolio cost = TIPS + swaps + STRIPS | B6: =B4+B5 -> 0
A8: Treasury note market (full) price | B8: ='Step1_Prices'!B26 -> 0
A9: Mispricing = Treasury - replicating portfolio | B9: =B8-B6 -> 0
A10: PxSTRIPS is negative: the STRIPS leg is net short (short at maturity) and returns 1.1887 today. Equivalently the package costs 97.0428 - 1.1887 = 95.8541, exactly as on the lecture slide.
A12: Adjusting for the ~1-month maturity mismatch (notebook 'Details')
A13: TIPS yield to maturity | B13: 0.0497
A14: Treasury note repriced at the TIPS yield (4.97%) | B14: 95.4583
A15: Mispricing (maturity-adjusted) = Treasury - repriced | B15: =B8-B14 -> 0
A17: TIPS maturity 7/15/2015 vs T-note 8/15/2015. The yield 4.97% and repriced value 95.4583 are computed in the notebook (Fleckenstein-Longstaff-Lustig 2014); entered here as inputs.
A19: Arbitrage: short the richer Treasury note at 98.0734 and buy the cheaper replicating package (TIPS + inflation swaps + STRIPS) at 95.8541, locking in about 2.22 per 100 notional (about 2.62 after the maturity adjustment).
